const assert = require('assert');

test('account test', async () => {
    try {
        const result = await someAsyncFunction();
        assert.strictEqual(result, expectedValue);
    } catch (error) {
        assert.fail(`Test failed due to unhandled error: ${error.message}`);
    }
});